<?xml version='1.0' encoding='utf-8'?>
<mujoco model="pupper_v2_dji">
  <compiler angle="radian" meshdir="meshes/" autolimits="true" />
  <asset>
    <mesh name="Cube.003" content_type="model/obj" file="Cube.003.obj" />
    <texture name="grid" type="2d" builtin="checker" width="512" height="512" rgb1=".2 .4 .6" rgb2=".4 .6 .8" />
    <material name="grid" texture="grid" texrepeat="1 1" texuniform="true" reflectance="0" />
  <mesh name="apriltag_quad" file="apriltag_quad.obj" scale="0.4 0.4 1.0" inertia="shell" /><texture name="apriltag_good_tex" type="2d" file="textures/apriltag_36h11_id101.png" /><texture name="apriltag_bad_tex" type="2d" file="textures/apriltag_36h11_id287.png" /><material name="apriltag_good_mat" texture="apriltag_good_tex" texuniform="true" texrepeat="1 1" reflectance="0" shininess="0" specular="0" /><material name="apriltag_bad_mat" texture="apriltag_bad_tex" texuniform="true" texrepeat="1 1" reflectance="0" shininess="0" specular="0" /><material name="room_wall_mat" rgba="0.92 0.92 0.92 1" /></asset>
  <worldbody>
    <body name="base_link" pos="0 0 0.20">
      <inertial pos="0 -0.048 -0.00964" quat="0.499924 0.500153 -0.497855 0.50206" mass="0.991" diaginertia="0.00678008 0.00626009 0.00174983" />
      <geom name="Cube" pos="0 0.1 0" quat="1 0 0 0" type="mesh" mesh="Cube.003" contype="0" conaffinity="0" />
      <body name="leftFrontLeg" pos="0.047 -0.1015 0">
        <inertial pos="0.0139 0.0254 0" quat="0.5 0.5 0.5 0.5" mass="0.106" diaginertia="6e-05 6e-05 2e-05" />
        <joint name="leftFrontLegMotor" pos="0 0 0" axis="0 -1 0" range="-0.7854 0.7854" />
        <geom name="Hip L" size="0.015" pos="0.0235 0.0265 0" quat="0.499998 0.5 -0.500002 -0.5" type="sphere" class="collision" contype="2" conaffinity="1" condim="3" group="1" />
        <body name="leftFrontUpperLeg" pos="0.0395 0.0265 0">
          <inertial pos="0.0172 0 -0.061" quat="0.707107 0 0 0.707107" mass="0.142" diaginertia="0.00016 0.00014 3e-05" />
          <joint name="leftFrontUpperLegMotor" pos="0 0 0" axis="1 0 0" range="-1.309 4.45059" />
          <geom name="Upper Leg - Pupper 2.1 v57" size="0.015" pos="0.0169 0 -0.08" quat="0.499998 0.5 0.500002 0.5" type="sphere" class="collision" contype="2" conaffinity="1" condim="3" group="1" />
          <body name="leftFrontLowerLeg" pos="-0.004 0 -0.08" quat="1.32679e-06 0 0 1">
            <inertial pos="0.0055706 -0.000748031 -0.065916" quat="0.776224 3.90663e-05 3.17301e-05 0.630458" mass="0.0381" diaginertia="0.000200196 0.000200195 4.00013e-05" />
            <joint name="leftFrontLowerLegMotor" pos="0 0 0" axis="-1 0 0" range="-2.87979 2.87979" />
            <geom name="Lower Leg L" size="0.004755 0.006 0.05379" pos="0.00699 0 -0.05223" type="box" contype="0" conaffinity="0" />
            <geom name="Sphere.003" size="0.0095" pos="0.002 0 -0.11" quat="1.32679e-06 0 0 -1" type="sphere" class="collision" contype="1" conaffinity="1" condim="3" group="1" />
            <site name="leftFrontLowerLeg_foot_site" pos="0.002 0 -0.11" />
          </body>
        </body>
      </body>
      <body name="leftRearLeg" pos="0.047 0.0985 0">
        <inertial pos="0.0139 0.0254 0" quat="0.5 0.5 0.5 0.5" mass="0.106" diaginertia="6e-05 6e-05 2e-05" />
        <joint name="leftRearLegMotor" pos="0 0 0" axis="0 -1 0" range="-0.7854 0.7854" />
        <geom size="0.015" pos="0.0235 0.0265 0" quat="0.499998 0.5 -0.500002 -0.5" type="sphere" class="collision" contype="2" conaffinity="1" condim="3" group="1" />
        <body name="leftRearUpperLeg" pos="0.0395 0.0265 0">
          <inertial pos="0.0172 0 -0.061" quat="0.707107 0 0 0.707107" mass="0.142" diaginertia="0.00016 0.00014 3e-05" />
          <joint name="leftRearUpperLegMotor" pos="0 0 0" axis="1 0 0" range="-1.309 4.45059" />
          <geom size="0.015" pos="0.0169 0 -0.08" quat="0.499998 0.5 0.500002 0.5" type="sphere" class="collision" contype="2" conaffinity="1" condim="3" group="1" />
          <body name="leftRearLowerLeg" pos="-0.004 0 -0.08" quat="1.32679e-06 0 0 1">
            <inertial pos="0.0055706 -0.000748031 -0.065916" quat="0.776224 3.90663e-05 3.17301e-05 0.630458" mass="0.0381" diaginertia="0.000200196 0.000200195 4.00013e-05" />
            <joint name="leftRearLowerLegMotor" pos="0 0 0" axis="-1 0 0" range="-2.87979 2.87979" />
            <geom size="0.004755 0.006 0.05379" pos="0.00699 0 -0.05223" type="box" contype="0" conaffinity="0" />
            <geom name="Sphere" size="0.0095" pos="0.002 0 -0.11" quat="1.32679e-06 0 0 -1" type="sphere" class="collision" contype="1" conaffinity="1" condim="3" group="1" />
            <site name="leftRearLowerLeg_foot_site" pos="0.002 0 -0.11" />
          </body>
        </body>
      </body>
      <body name="rightFrontLeg" pos="-0.047 -0.103 0" quat="1.32679e-06 0 0 -1">
        <inertial pos="0.0139 -0.0269 0" quat="0.5 0.5 0.5 0.5" mass="0.106" diaginertia="6e-05 6e-05 2e-05" />
        <joint name="rightFrontLegMotor" pos="0 0 0" axis="0 1 0" range="-0.7854 0.7854" />
        <geom name="Hip R" size="0.015" pos="0.0235 -0.028 0" quat="0.499998 0.5 -0.500002 -0.5" type="sphere" class="collision" contype="2" conaffinity="1" condim="3" group="1" />
        <body name="rightFrontUpperLeg" pos="0.0395 -0.028 0">
          <inertial pos="0.0172 0 -0.061" quat="0.707107 0 0 0.707107" mass="0.142" diaginertia="0.00016 0.00014 3e-05" />
          <joint name="rightFrontUpperLegMotor" pos="0 0 0" axis="-1 0 0" range="-1.309 4.45059" />
          <geom size="0.015" pos="0.0169 0 -0.08" quat="0.499998 0.5 -0.500002 -0.5" type="sphere" class="collision" contype="2" conaffinity="1" condim="3" group="1" />
          <body name="rightFrontLowerLeg" pos="-0.004 0 -0.08">
            <inertial pos="-0.00586982 -0.000748031 -0.065916" quat="0.63648 -3.4609e-05 -4.19395e-05 0.771293" mass="0.0381" diaginertia="0.000200196 0.000200195 4.00016e-05" />
            <joint name="rightFrontLowerLegMotor" pos="0 0 0" axis="-1 0 0" range="-2.87979 2.87979" />
            <geom name="Lower Leg R" size="0.004765 0.006 0.05379" pos="-0.00698 0 -0.05223" type="box" contype="0" conaffinity="0" />
            <geom name="Sphere.002" size="0.0095" pos="-0.002 0 -0.11" quat="1.32679e-06 0 0 1" type="sphere" class="collision" contype="1" conaffinity="1" condim="3" group="1" />
            <site name="rightFrontLowerLeg_foot_site" pos="-0.002 0 -0.11" />
          </body>
        </body>
      </body>
      <body name="rightRearLeg" pos="-0.047 0.097 0" quat="1.32679e-06 0 0 -1">
        <inertial pos="0.0139 -0.0269 0" quat="0.5 0.5 0.5 0.5" mass="0.106" diaginertia="6e-05 6e-05 2e-05" />
        <joint name="rightRearLegMotor" pos="0 0 0" axis="0 1 0" range="-0.7854 0.7854" />
        <geom size="0.015" pos="0.0235 -0.028 0" quat="0.499998 0.5 -0.500002 -0.5" type="sphere" class="collision" contype="2" conaffinity="1" condim="3" group="1" />
        <body name="rightRearUpperLeg" pos="0.0395 -0.028 0">
          <inertial pos="0.0172 0 -0.061" quat="0.707107 0 0 0.707107" mass="0.142" diaginertia="0.00016 0.00014 3e-05" />
          <joint name="rightRearUpperLegMotor" pos="0 0 0" axis="-1 0 0" range="-1.309 4.45059" />
          <geom size="0.015" pos="0.0169 0 -0.08" quat="0.499998 0.5 -0.500002 -0.5" type="sphere" class="collision" contype="2" conaffinity="1" condim="3" group="1" />
          <body name="rightRearLowerLeg" pos="-0.004 0 -0.08">
            <inertial pos="-0.00586982 -0.000748031 -0.065916" quat="0.63648 -3.4609e-05 -4.19395e-05 0.771293" mass="0.0381" diaginertia="0.000200196 0.000200195 4.00016e-05" />
            <joint name="rightRearLowerLegMotor" pos="0 0 0" axis="-1 0 0" range="-2.87979 2.87979" />
            <geom size="0.004765 0.006 0.05379" pos="-0.00698 0 -0.05223" type="box" contype="0" conaffinity="0" />
            <geom name="Sphere.001" size="0.0095" pos="-0.002 0 -0.11" quat="1.32679e-06 0 0 1" type="sphere" class="collision" contype="1" conaffinity="1" condim="3" group="1" />
            <site name="rightRearLowerLeg_foot_site" pos="-0.002 0 -0.11" />
          </body>
        </body>
      </body>
      <freejoint name="base_link_freejoint" />
      <site name="body_imu_site" pos="0.09 0 0.032" />
      <geom name="base_collision" type="box" size="0.070 0.055 0.025" pos="0 0.100 0.010" class="collision" contype="1" conaffinity="1" condim="3" group="3" rgba="0 0 0 0" />
    <camera name="front_cam" pos="0.0001 -0.147 -0.0064" xyaxes="-1 0 0 0 0 1" fovy="48.8" /></body>
    <geom name="floor" size="0 0 .05" type="plane" material="grid" condim="3" contype="1" conaffinity="1" />
    <geom name="floor_visual" size="0 0 .05" pos="0 0 -0.001" type="plane" material="grid" condim="3" contype="0" conaffinity="0" group="1" />
    <light name="spotlight" mode="targetbodycom" target="base_link" diffuse="1.0 1.0 1.0" specular="0.35 0.35 0.35" ambient="0.20 0.20 0.20" pos="0 -4 4" cutoff="100" castshadow="false" />
    <light name="back_fill" mode="targetbodycom" target="base_link" diffuse="0.55 0.55 0.55" specular="0.12 0.12 0.12" ambient="0.10 0.10 0.10" pos="0 3.5 2.5" cutoff="100" castshadow="false" />
    <camera name="tracking_cam" mode="targetbody" target="base_link" pos="0.5 -0.5 0.5" />
  <geom name="room_wall_front" type="box" pos="0 -1.8 0.6" size="3.3 0.3 0.6" material="room_wall_mat" contype="1" conaffinity="1" condim="3" friction="0.4 0.005 0.0001" /><geom name="room_wall_back" type="box" pos="0 1.8 0.6" size="3.3 0.3 0.6" material="room_wall_mat" contype="1" conaffinity="1" condim="3" friction="0.4 0.005 0.0001" /><geom name="room_wall_left" type="box" pos="-3.0 0 0.6" size="0.3 1.8 0.6" material="room_wall_mat" contype="1" conaffinity="1" condim="3" friction="0.4 0.005 0.0001" /><geom name="room_wall_right" type="box" pos="3.0 0 0.6" size="0.3 1.8 0.6" material="room_wall_mat" contype="1" conaffinity="1" condim="3" friction="0.4 0.005 0.0001" /><geom name="room_wall_l4_v1a" type="box" pos="-0.6 0.9 0.6" size="0.3 0.6 0.6" material="room_wall_mat" contype="1" conaffinity="1" condim="3" friction="0.4 0.005 0.0001" /><geom name="room_wall_l4_v1b" type="box" pos="-0.6 -0.6 0.6" size="0.3 0.3 0.6" material="room_wall_mat" contype="1" conaffinity="1" condim="3" friction="0.4 0.005 0.0001" /><geom name="room_wall_l4_h1" type="box" pos="1.2 0.6 0.6" size="0.9 0.3 0.6" material="room_wall_mat" contype="1" conaffinity="1" condim="3" friction="0.4 0.005 0.0001" /><geom name="room_wall_l4_v2" type="box" pos="0.6 0.0 0.6" size="0.3 0.9 0.6" material="room_wall_mat" contype="1" conaffinity="1" condim="3" friction="0.4 0.005 0.0001" /><geom name="apriltag_good_panel" type="mesh" mesh="apriltag_quad" pos="0.0 -1.46 0.25" quat="0.70710678 -0.70710678 0 0" material="apriltag_good_mat" contype="0" conaffinity="0" group="1" /></worldbody>
  <default>
    <geom condim="3" contype="0" conaffinity="0" group="1" />
    <joint armature="0.0016" type="hinge" damping="0.01" frictionloss="0.125" limited="true" />
    <general forcerange="-3 3" forcelimited="true" biastype="affine" gainprm="5.0 0 0" biasprm="0 -5.0 -0.1" />
    <default class="collision">
      <geom group="3" contype="1" conaffinity="1" condim="3" solimp="0.015 1 0.031" friction="0.8 0.02 0.01" />
    </default>
  </default>
  <actuator>
    <general joint="rightFrontLegMotor" name="rightFrontLegMotor" />
    <general joint="rightFrontUpperLegMotor" name="rightFrontUpperLegMotor" />
    <general joint="rightFrontLowerLegMotor" name="rightFrontLowerLegMotor" />
    <general joint="leftFrontLegMotor" name="leftFrontLegMotor" />
    <general joint="leftFrontUpperLegMotor" name="leftFrontUpperLegMotor" />
    <general joint="leftFrontLowerLegMotor" name="leftFrontLowerLegMotor" />
    <general joint="rightRearLegMotor" name="rightRearLegMotor" />
    <general joint="rightRearUpperLegMotor" name="rightRearUpperLegMotor" />
    <general joint="rightRearLowerLegMotor" name="rightRearLowerLegMotor" />
    <general joint="leftRearLegMotor" name="leftRearLegMotor" />
    <general joint="leftRearUpperLegMotor" name="leftRearUpperLegMotor" />
    <general joint="leftRearLowerLegMotor" name="leftRearLowerLegMotor" />
  </actuator>
  <option cone="pyramidal" impratio="10" iterations="2" ls_iterations="5" timestep="0.004">
    <flag eulerdamp="disable" />
  </option>
  <custom>
    <numeric name="max_contact_points" data="5" />
    <numeric name="max_geom_pairs" data="4" />
  </custom>
</mujoco>
