<mujoco model="pupper_v2_dji">
  <compiler angle="radian" meshdir="meshes/"/>

  <asset>
    <mesh name="Cube.003" content_type="model/obj" file="Cube.003.obj"/>
  </asset>

  <worldbody>
    <body name="pupper_v2_dji_chassis">
      <inertial pos="0 -0.048 -0.00964" quat="0.499924 0.500153 -0.497855 0.50206" mass="0.991" diaginertia="0.00678008 0.00626009 0.00174983"/>
      <joint name="world_to_body" type="free"/>
      <geom name="Cube" pos="0 0.1 0" quat="1 0 0 0" type="mesh" mesh="Cube.003"/>
      <body name="leftFrontLeg" pos="0.047 -0.1015 0">
        <inertial pos="0.0139 0.0254 0" quat="0.5 0.5 0.5 0.5" mass="0.106" diaginertia="6e-05 6e-05 2e-05"/>
        <joint name="leftFrontLegMotor" pos="0 0 0" axis="0 -1 0" range="-0.7854 0.7854"/>
        <geom name="Hip L" size="0.015 0.0375" pos="0.0235 0.0265 0" quat="0.499998 0.5 -0.500002 -0.5" type="cylinder"/>
        <body name="leftFrontUpperLeg" pos="0.0395 0.0265 0">
          <inertial pos="0.0172 0 -0.061" quat="0.707107 0 0 0.707107" mass="0.142" diaginertia="0.00016 0.00014 3e-05"/>
          <joint name="leftFrontUpperLegMotor" pos="0 0 0" axis="1 0 0" range="-1.309 4.45059"/>
          <geom name="Upper Leg - Pupper 2.1 v57" size="0.015 0.0325" pos="0.0169 0 -0.08" quat="0.499998 0.5 0.500002 0.5" type="cylinder"/>
          <body name="leftFrontLowerLeg" pos="-0.004 0 -0.08" quat="1.32679e-06 0 0 1">
            <inertial pos="0.0055706 -0.000748031 -0.065916" quat="0.776224 3.90663e-05 3.17301e-05 0.630458" mass="0.0381" diaginertia="0.000200196 0.000200195 4.00013e-05"/>
            <joint name="leftFrontLowerLegMotor" pos="0 0 0" axis="-1 0 0" range="-2.87979 2.87979"/>
            <geom name="Lower Leg L" size="0.004755 0.006 0.05379" pos="0.00699 0 -0.05223" type="box"/>
            <geom name="Sphere.003" size="0.0095" pos="0.002 0 -0.11" quat="1.32679e-06 0 0 -1"/>
          </body>
        </body>
      </body>
      <body name="leftRearLeg" pos="0.047 0.0985 0">
        <inertial pos="0.0139 0.0254 0" quat="0.5 0.5 0.5 0.5" mass="0.106" diaginertia="6e-05 6e-05 2e-05"/>
        <joint name="leftRearLegMotor" pos="0 0 0" axis="0 -1 0" range="-0.7854 0.7854"/>
        <geom size="0.015 0.0375" pos="0.0235 0.0265 0" quat="0.499998 0.5 -0.500002 -0.5" type="cylinder"/>
        <body name="leftRearUpperLeg" pos="0.0395 0.0265 0">
          <inertial pos="0.0172 0 -0.061" quat="0.707107 0 0 0.707107" mass="0.142" diaginertia="0.00016 0.00014 3e-05"/>
          <joint name="leftRearUpperLegMotor" pos="0 0 0" axis="1 0 0" range="-1.309 4.45059"/>
          <geom size="0.015 0.0325" pos="0.0169 0 -0.08" quat="0.499998 0.5 0.500002 0.5" type="cylinder"/>
          <body name="leftRearLowerLeg" pos="-0.004 0 -0.08" quat="1.32679e-06 0 0 1">
            <inertial pos="0.0055706 -0.000748031 -0.065916" quat="0.776224 3.90663e-05 3.17301e-05 0.630458" mass="0.0381" diaginertia="0.000200196 0.000200195 4.00013e-05"/>
            <joint name="leftRearLowerLegMotor" pos="0 0 0" axis="-1 0 0" range="-2.87979 2.87979"/>
            <geom size="0.004755 0.006 0.05379" pos="0.00699 0 -0.05223" type="box"/>
            <geom name="Sphere" size="0.0095" pos="0.002 0 -0.11" quat="1.32679e-06 0 0 -1"/>
          </body>
        </body>
      </body>
      <body name="rightFrontLeg" pos="-0.047 -0.103 0" quat="1.32679e-06 0 0 -1">
        <inertial pos="0.0139 -0.0269 0" quat="0.5 0.5 0.5 0.5" mass="0.106" diaginertia="6e-05 6e-05 2e-05"/>
        <joint name="rightFrontLegMotor" pos="0 0 0" axis="0 1 0" range="-0.7854 0.7854"/>
        <geom name="Hip R" size="0.015 0.0375" pos="0.0235 -0.028 0" quat="0.499998 0.5 -0.500002 -0.5" type="cylinder"/>
        <body name="rightFrontUpperLeg" pos="0.0395 -0.028 0">
          <inertial pos="0.0172 0 -0.061" quat="0.707107 0 0 0.707107" mass="0.142" diaginertia="0.00016 0.00014 3e-05"/>
          <joint name="rightFrontUpperLegMotor" pos="0 0 0" axis="-1 0 0" range="-1.309 4.45059"/>
          <geom size="0.015 0.0325" pos="0.0169 0 -0.08" quat="0.499998 0.5 -0.500002 -0.5" type="cylinder"/>
          <body name="rightFrontLowerLeg" pos="-0.004 0 -0.08">
            <inertial pos="-0.00586982 -0.000748031 -0.065916" quat="0.63648 -3.4609e-05 -4.19395e-05 0.771293" mass="0.0381" diaginertia="0.000200196 0.000200195 4.00016e-05"/>
            <joint name="rightFrontLowerLegMotor" pos="0 0 0" axis="-1 0 0" range="-2.87979 2.87979"/>
            <geom name="Lower Leg R" size="0.004765 0.006 0.05379" pos="-0.00698 0 -0.05223" type="box"/>
            <geom name="Sphere.002" size="0.0095" pos="-0.002 0 -0.11" quat="1.32679e-06 0 0 1"/>
          </body>
        </body>
      </body>
      <body name="rightRearLeg" pos="-0.047 0.097 0" quat="1.32679e-06 0 0 -1">
        <inertial pos="0.0139 -0.0269 0" quat="0.5 0.5 0.5 0.5" mass="0.106" diaginertia="6e-05 6e-05 2e-05"/>
        <joint name="rightRearLegMotor" pos="0 0 0" axis="0 1 0" range="-0.7854 0.7854"/>
        <geom size="0.015 0.0375" pos="0.0235 -0.028 0" quat="0.499998 0.5 -0.500002 -0.5" type="cylinder"/>
        <body name="rightRearUpperLeg" pos="0.0395 -0.028 0">
          <inertial pos="0.0172 0 -0.061" quat="0.707107 0 0 0.707107" mass="0.142" diaginertia="0.00016 0.00014 3e-05"/>
          <joint name="rightRearUpperLegMotor" pos="0 0 0" axis="-1 0 0" range="-1.309 4.45059"/>
          <geom size="0.015 0.0325" pos="0.0169 0 -0.08" quat="0.499998 0.5 -0.500002 -0.5" type="cylinder"/>
          <body name="rightRearLowerLeg" pos="-0.004 0 -0.08">
            <inertial pos="-0.00586982 -0.000748031 -0.065916" quat="0.63648 -3.4609e-05 -4.19395e-05 0.771293" mass="0.0381" diaginertia="0.000200196 0.000200195 4.00016e-05"/>
            <joint name="rightRearLowerLegMotor" pos="0 0 0" axis="-1 0 0" range="-2.87979 2.87979"/>
            <geom size="0.004765 0.006 0.05379" pos="-0.00698 0 -0.05223" type="box"/>
            <geom name="Sphere.001" size="0.0095" pos="-0.002 0 -0.11" quat="1.32679e-06 0 0 1"/>
          </body>
        </body>
      </body>
    </body>
  </worldbody>
</mujoco>
